Workbook

Sheet Raw_Data
A1: claim_id | B1: policy_id | C1: claim_type | D1: claim_amount | E1: days_since_policy_start | F1: num_prior_claims | G1: incident_report_delay_days | H1: is_weekend_claim | I1: claim_channel | J1: fraud_label | K1: age | L1: gender | M1: postcode_region | N1: income_band | O1: policy_type | P1: policy_tenure_years | Q1: claim_amount_outlier | R1: baseline_flag
A2: 200001 | B2: 52306 | C2: Motor | D2: 1171.62 | E2: 42 | F2: 0 | G2: 4 | H2: 0 | I2: Phone | J2: 0 | K2: 79 | L2: Male | M2: South | N2: Medium | O2: Premium | P2: 3.65 | Q2: =FALSE() -> FALSE | R2: 0
A3: 200002 | B3: 50795 | C3: Motor | D3: 1192.21 | E3: 3024 | F3: 2 | G3: 6 | H3: 1 | I3: Phone | J3: 0 | K3: 80 | L3: Female | M3: Scotland | N3: High | O3: Standard | P3: 0.12 | Q3: =FALSE() -> FALSE | R3: 0
A4: 200003 | B4: 55049 | C4: Travel | D4: 3567.16 | E4: 2241 | F4: 1 | G4: 6 | H4: 0 | I4: Phone | J4: 0 | K4: 77 | L4: Female | M4: North | N4: Low | O4: Standard | P4: 3.87 | Q4: =FALSE() -> FALSE | R4: 0
A5: 200004 | B5: 52126 | C5: Motor | D5: 1311.54 | E5: 970 | F5: 0 | G5: 4 | H5: 0 | I5: Phone | J5: 0 | K5: 51 | L5: Female | M5: London | N5: Medium | O5: Premium | P5: 4.01 | Q5: =FALSE() -> FALSE | R5: 0
A6: 200005 | B6: 55662 | C6: Motor | D6: 1237.59 | E6: 3538 | F6: 1 | G6: 0 | H6: 0 | I6: Broker | J6: 0 | K6: 44 | L6: Male | M6: London | N6: Medium | O6: Premium | P6: 3.11 | Q6: =FALSE() -> FALSE | R6: 0
A7: 200006 | B7: 51460 | C7: Motor | D7: 6705.69 | E7: 604 | F7: 0 | G7: 5 | H7: 1 | I7: Phone | J7: 0 | K7: 23 | L7: Female | M7: Scotland | N7: Low | O7: Standard | P7: 0.97 | Q7: =FALSE() -> FALSE | R7: 1
A8: 200007 | B8: 51990 | C8: Motor | D8: 1411.26 | E8: 1067 | F8: 3 | G8: 4 | H8: 0 | I8: Phone | J8: 0 | K8: 54 | L8: Female | M8: South | N8: Medium | O8: Standard | P8: 0.29 | Q8: =FALSE() -> FALSE | R8: 1
A9: 200008 | B9: 50029 | C9: Motor | D9: 3183.48 | E9: 114 | F9: 0 | G9: 4 | H9: 0 | I9: Online | J9: 0 | K9: 42 | L9: Female | M9: London | N9: Medium | O9: Standard | P9: 1.52 | Q9: =FALSE() -> FALSE | R9: 0
A10: 200009 | B10: 52691 | C10: Home | D10: 2017.59 | E10: 3214 | F10: 0 | G10: 3 | H10: 0 | I10: Broker | J10: 0 | K10: 59 | L10: Female | M10: Midlands | N10: Low | O10: Basic | P10: 3.52 | Q10: =FALSE() -> FALSE | R10: 0
A11: 200010 | B11: 54535 | C11: Home | D11: 1885.14 | E11: 3123 | F11: 2 | G11: 6 | H11: 0 | I11: Phone | J11: 0 | K11: 29 | L11: Female | M11: South | N11: High | O11: Basic | P11: 0.69 | Q11: =FALSE() -> FALSE | R11: 0
A12: 200011 | B12: 51052 | C12: Home | D12: 1345.32 | E12: 229 | F12: 2 | G12: 5 | H12: 0 | I12: Broker | J12: 0 | K12: 53 | L12: Female | M12: South | N12: Medium | O12: Basic | P12: 2.99 | Q12: =FALSE() -> FALSE | R12: 0
A13: 200012 | B13: 54858 | C13: Home | D13: 1077.33 | E13: 1655 | F13: 1 | G13: 4 | H13: 0 | I13: Phone | J13: 0 | K13: 69 | L13: Male | M13: Scotland | N13: Low | O13: Standard | P13: 2.27 | Q13: =FALSE() -> FALSE | R13: 0
... A17: 200016 | B17: 50917 | C17: Travel | D17: 1179.38 | E17: 1977 | F17: 2 | G17: 1 | H17: 0 | I17: Online | J17: 1 | K17: 78 | L17: Male | M17: Wales | N17: High | O17: Standard | P17: 2.44 | Q17: =FALSE() -> FALSE | R17: 0
A18: 200017 | B18: 54514 | C18: Motor | D18: 7989.15 | E18: 72 | F18: 0 | G18: 5 | H18: 0 | I18: Online | J18: 0 | K18: 65 | L18: Male | M18: London | N18: Low | O18: Standard | P18: 2.39 | Q18: =TRUE() -> TRUE | R18: 1
A19: 200018 | B19: 55415 | C19: Home | D19: 1129.62 | E19: 1836 | F19: 0 | G19: 6 | H19: 0 | I19: Phone | J19: 1 | K19: 58 | L19: Male | M19: South | N19: High | O19: Standard | P19: 0.01 | Q19: =FALSE() -> FALSE | R19: 0
A20: 200019 | B20: 55146 | C20: Home | D20: 2931.98 | E20: 2309 | F20: 1 | G20: 6 | H20: 0 | I20: Online | J20: 0 | K20: 21 | L20: Male | M20: North | N20: Medium | O20: Basic | P20: 2.4 | Q20: =FALSE() -> FALSE | R20: 0
A21: 200020 | B21: 53397 | C21: Motor | D21: 2458.28 | E21: 594 | F21: 0 | G21: 2 | H21: 0 | I21: Online | J21: 0 | K21: 21 | L21: Female | M21: North | N21: Medium | O21: Basic | P21: 2.67 | Q21: =FALSE() -> FALSE | R21: 0
A22: 200021 | B22: 55108 | C22: Home | D22: 552.26 | E22: 3597 | F22: 0 | G22: 2 | H22: 1 | I22: Phone | J22: 0 | K22: 68 | L22: Male | M22: Wales | N22: High | O22: Premium | P22: 0.82 | Q22: =FALSE() -> FALSE | R22: 0
A23: 200022 | B23: 55745 | C23: Motor | D23: 693.07 | E23: 343 | F23: 0 | G23: 2 | H23: 0 | I23: Broker | J23: 1 | K23: 21 | L23: Female | M23: South | N23: Low | O23: Standard | P23: 1.4 | Q23: =FALSE() -> FALSE | R23: 0
A24: 200023 | B24: 51853 | C24: Home | D24: 4236.42 | E24: 2159 | F24: 1 | G24: 2 | H24: 0 | I24: Phone | J24: 0 | K24: 30 | L24: Female | M24: South | N24: Low | O24: Basic | P24: 5.78 | Q24: =FALSE() -> FALSE | R24: 1
A25: 200024 | B25: 51787 | C25: Motor | D25: 2827.56 | E25: 444 | F25: 2 | G25: 2 | H25: 1 | I25: Online | J25: 0 | K25: 42 | L25: Male | M25: Scotland | N25: High | O25: Basic | P25: 2.6 | Q25: =FALSE() -> FALSE | R25: 0
A26: 200025 | B26: 50202 | C26: Home | D26: 3316.87 | E26: 2494 | F26: 0 | G26: 4 | H26: 0 | I26: Phone | J26: 1 | K26: 59 | L26: Male | M26: South | N26: High | O26: Standard | P26: 0.51 | Q26: =FALSE() -> FALSE | R26: 0
A27: 200026 | B27: 53189 | C27: Motor | D27: 2239.53 | E27: 3117 | F27: 0 | G27: 1 | H27: 1 | I27: Online | J27: 0 | K27: 26 | L27: Male | M27: London | N27: Medium | O27: Basic | P27: 0.95 | Q27: =FALSE() -> FALSE | R27: 0
A28: 200027 | B28: 53120 | C28: Travel | D28: 597.96 | E28: 99 | F28: 0 | G28: 3 | H28: 0 | I28: Online | J28: 0 | K28: 26 | L28: Male | M28: Midlands | N28: Medium | O28: Standard | P28: 7.6 | Q28: =FALSE() -> FALSE | R28: 0
A29: 200028 | B29: 55534 | C29: Home | D29: 5502.59 | E29: 1581 | F29: 2 | G29: 4 | H29: 0 | I29: Online | J29: 0 | K29: 76 | L29: Male | M29: Scotland | N29: Medium | O29: Standard | P29: 4.36 | Q29: =FALSE() -> FALSE | R29: 1
A30: 200029 | B30: 54757 | C30: Motor | D30: 3994.26 | E30: 3511 | F30: 2 | G30: 2 | H30: 0 | I30: Online | J30: 0 | K30: 36 | L30: Male | M30: Wales | N30: Low | O30: Premium | P30: 0.25 | Q30: =FALSE() -> FALSE | R30: 1
... A36: 200035 | B36: 54393 | C36: Motor | D36: 2755.09 | E36: 3165 | F36: 2 | G36: 5 | H36: 1 | I36: Phone | J36: 1 | K36: 72 | L36: Female | M36: North | N36: Low | O36: Standard | P36: 1.49 | Q36: =FALSE() -> FALSE | R36: 0
A37: 200036 | B37: 51270 | C37: Home | D37: 8117.04 | E37: 2841 | F37: 0 | G37: 2 | H37: 0 | I37: Phone | J37: 0 | K37: 22 | L37: Male | M37: London | N37: Medium | O37: Standard | P37: 0.62 | Q37: =TRUE() -> TRUE | R37: 1
A38: 200037 | B38: 51985 | C38: Motor | D38: 2642.62 | E38: 2552 | F38: 1 | G38: 3 | H38: 0 | I38: Online | J38: 0 | K38: 25 | L38: Female | M38: Scotland | N38: High | O38: Standard | P38: 3.76 | Q38: =FALSE() -> FALSE | R38: 0
A39: 200038 | B39: 50976 | C39: Home | D39: 4036.99 | E39: 949 | F39: 3 | G39: 4 | H39: 1 | I39: Broker | J39: 0 | K39: 67 | L39: Female | M39: London | N39: Low | O39: Basic | P39: 0.79 | Q39: =FALSE() -> FALSE | R39: 1
A40: 200039 | B40: 55636 | C40: Home | D40: 3172.48 | E40: 1307 | F40: 4 | G40: 6 | H40: 0 | I40: Phone | J40: 0 | K40: 26 | L40: Female | M40: Midlands | N40: Medium | O40: Basic | P40: 2.14 | Q40: =FALSE() -> FALSE | R40: 1
A41: 200040 | B41: 54389 | C41: Motor | D41: 3549.58 | E41: 3112 | F41: 1 | G41: 4 | H41: 0 | I41: Online | J41: 0 | K41: 59 | L41: Female | M41: North | N41: High | O41: Standard | P41: 0.71 | Q41: =FALSE() -> FALSE | R41: 0
A42: 200041 | B42: 52530 | C42: Motor | D42: 4798.21 | E42: 2511 | F42: 2 | G42: 9 | H42: 0 | I42: Online | J42: 0 | K42: 32 | L42: Female | M42: South | N42: Medium | O42: Premium | P42: 1.17 | Q42: =FALSE() -> FALSE | R42: 1
A43: 200042 | B43: 51958 | C43: Motor | D43: 684.49 | E43: 2020 | F43: 1 | G43: 5 | H43: 0 | I43: Broker | J43: 1 | K43: 77 | L43: Female | M43: Scotland | N43: Low | O43: Standard | P43: 1.18 | Q43: =FALSE() -> FALSE | R43: 0
A44: 200043 | B44: 53722 | C44: Home | D44: 1018.53 | E44: 1899 | F44: 2 | G44: 5 | H44: 0 | I44: Online | J44: 0 | K44: 62 | L44: Male | M44: London | N44: Medium | O44: Premium | P44: 5.4 | Q44: =FALSE() -> FALSE | R44: 0
A45: 200044 | B45: 55170 | C45: Home | D45: 3928.5 | E45: 2235 | F45: 0 | G45: 2 | H45: 0 | I45: Online | J45: 0 | K45: 57 | L45: Male | M45: North | N45: Medium | O45: Basic | P45: 0.67 | Q45: =FALSE() -> FALSE | R45: 1
A46: 200045 | B46: 51492 | C46: Home | D46: 1249.21 | E46: 1009 | F46: 0 | G46: 3 | H46: 0 | I46: Phone | J46: 0 | K46: 73 | L46: Female | M46: North | N46: Low | O46: Basic | P46: 4.04 | Q46: =FALSE() -> FALSE | R46: 0
A47: 200046 | B47: 52275 | C47: Home | D47: 3130.16 | E47: 867 | F47: 0 | G47: 4 | H47: 1 | I47: Broker | J47: 0 | K47: 59 | L47: Male | M47: North | N47: High | O47: Basic | P47: 0.21 | Q47: =FALSE() -> FALSE | R47: 0
A48: 200047 | B48: 50292 | C48: Motor | D48: 2622.38 | E48: 378 | F48: 1 | G48: 5 | H48: 0 | I48: Online | J48: 0 | K48: 51 | L48: Male | M48: Midlands | N48: Low | O48: Standard | P48: 0.69 | Q48: =FALSE() -> FALSE | R48: 0
...

Sheet Helper
A1: claim_amount_if_legit | B1: claim_amount_if_fraud
A2: =IF(Raw_Data!J2=0,Raw_Data!D2,"") -> 1171.62 | B2: =IF(Raw_Data!J2=1,Raw_Data!D2,"")
A3: =IF(Raw_Data!J3=0,Raw_Data!D3,"") -> 1192.21 | B3: =IF(Raw_Data!J3=1,Raw_Data!D3,"")
A4: =IF(Raw_Data!J4=0,Raw_Data!D4,"") -> 3567.16 | B4: =IF(Raw_Data!J4=1,Raw_Data!D4,"")
A5: =IF(Raw_Data!J5=0,Raw_Data!D5,"") -> 1311.54 | B5: =IF(Raw_Data!J5=1,Raw_Data!D5,"")
A6: =IF(Raw_Data!J6=0,Raw_Data!D6,"") -> 1237.59 | B6: =IF(Raw_Data!J6=1,Raw_Data!D6,"")
A7: =IF(Raw_Data!J7=0,Raw_Data!D7,"") -> 6705.69 | B7: =IF(Raw_Data!J7=1,Raw_Data!D7,"")
A8: =IF(Raw_Data!J8=0,Raw_Data!D8,"") -> 1411.26 | B8: =IF(Raw_Data!J8=1,Raw_Data!D8,"")
A9: =IF(Raw_Data!J9=0,Raw_Data!D9,"") -> 3183.48 | B9: =IF(Raw_Data!J9=1,Raw_Data!D9,"")
A10: =IF(Raw_Data!J10=0,Raw_Data!D10,"") -> 2017.59 | B10: =IF(Raw_Data!J10=1,Raw_Data!D10,"")
A11: =IF(Raw_Data!J11=0,Raw_Data!D11,"") -> 1885.14 | B11: =IF(Raw_Data!J11=1,Raw_Data!D11,"")
A12: =IF(Raw_Data!J12=0,Raw_Data!D12,"") -> 1345.32 | B12: =IF(Raw_Data!J12=1,Raw_Data!D12,"")
A13: =IF(Raw_Data!J13=0,Raw_Data!D13,"") -> 1077.33 | B13: =IF(Raw_Data!J13=1,Raw_Data!D13,"")
... A6001: =IF(Raw_Data!J6001=0,Raw_Data!D6001,"") | B6001: =IF(Raw_Data!J6001=1,Raw_Data!D6001,"") -> 1847.13

Sheet EDA_Validation
A1: AuroraSure Fraud Detection - EDA Validation Workbook
A4: Column key | B4: Notebook output (Python) | C4: Excel formula result | D4: Match?
A6: A. Dataset Overview
A7: Metric | B7: Notebook output | C7: Excel formula result | D7: Match?
A8: Number of claim records | B8: 6000 | C8: =COUNTA(Raw_Data!$A$2:$A$6001) -> 6000 | D8: =IF(ABS(B8-C8)<0.5,"OK","CHECK") -> OK
A9: Number of confirmed fraud cases | B9: 1105 | C9: =SUM(Raw_Data!$J$2:$J$6001) -> 1105 | D9: =IF(ABS(B9-C9)<0.5,"OK","CHECK") -> OK
A10: Percentage of claims labelled fraudulent | B10: 0.184167 | C10: =AVERAGE(Raw_Data!$J$2:$J$6001) -> 0.18416667 | D10: =IF(ABS(B10-C10)<0.001,"OK","CHECK") -> OK
A12: B. Fraud Rate by Claim Type
A13: Metric | B13: Notebook output | C13: Excel formula result | D13: Match?
A14: Fraud rate - Motor | B14: 0.182874 | C14: =AVERAGEIF(Raw_Data!$C$2:$C$6001,"Motor",Raw_Data!$J$2:$J$6001) -> 0.18287421 | D14: =IF(ABS(B14-C14)<0.001,"OK","CHECK") -> OK
A15: Fraud rate - Home | B15: 0.168396 | C15: =AVERAGEIF(Raw_Data!$C$2:$C$6001,"Home",Raw_Data!$J$2:$J$6001) -> 0.16839623 | D15: =IF(ABS(B15-C15)<0.001,"OK","CHECK") -> OK
A16: Fraud rate - Travel | B16: 0.22722 | C16: =AVERAGEIF(Raw_Data!$C$2:$C$6001,"Travel",Raw_Data!$J$2:$J$6001) -> 0.2272203 | D16: =IF(ABS(B16-C16)<0.001,"OK","CHECK") -> OK
A18: C. Summary Statistics (claim_amount)
A19: Metric | B19: Notebook output | C19: Excel formula result | D19: Match?
A20: Mean claim_amount | B20: 2659.4018 | C20: =AVERAGE(Raw_Data!$D$2:$D$6001) -> 2659.4018 | D20: =IF(ABS(B20-C20)<0.001,"OK","CHECK") -> OK
A21: Median claim_amount | B21: 2277.575 | C21: =MEDIAN(Raw_Data!$D$2:$D$6001) -> 2277.575 | D21: =IF(ABS(B21-C21)<0.001,"OK","CHECK") -> OK
A22: Standard deviation claim_amount | B22: 1789.7603 | C22: =STDEV(Raw_Data!$D$2:$D$6001) -> 1789.7603 | D22: =IF(ABS(B22-C22)<0.001,"OK","CHECK") -> OK
A23: Q1 claim_amount | B23: 1330.1625 | C23: =QUARTILE(Raw_Data!$D$2:$D$6001,1) -> 1330.1625 | D23: =IF(ABS(B23-C23)<0.001,"OK","CHECK") -> OK
A24: Q3 claim_amount | B24: 3570.395 | C24: =QUARTILE(Raw_Data!$D$2:$D$6001,3) -> 3570.395 | D24: =IF(ABS(B24-C24)<0.001,"OK","CHECK") -> OK
A25: IQR claim_amount | B25: 2240.2325 | C25: =C24-C23 -> 2240.2325 | D25: =IF(ABS(B25-C25)<0.001,"OK","CHECK") -> OK
A27: C. Summary Statistics (incident_report_delay_days)
A28: Metric | B28: Notebook output | C28: Excel formula result | D28: Match?
A29: Mean incident_report_delay_days | B29: 4.014 | C29: =AVERAGE(Raw_Data!$G$2:$G$6001) -> 4.014 | D29: =IF(ABS(B29-C29)<0.001,"OK","CHECK") -> OK
A30: Median incident_report_delay_days | B30: 4 | C30: =MEDIAN(Raw_Data!$G$2:$G$6001) -> 4 | D30: =IF(ABS(B30-C30)<0.001,"OK","CHECK") -> OK
A31: Standard deviation incident_report_delay_days | B31: 1.9862 | C31: =STDEV(Raw_Data!$G$2:$G$6001) -> 1.9862347 | D31: =IF(ABS(B31-C31)<0.001,"OK","CHECK") -> OK
A32: Q1 incident_report_delay_days | B32: 3 | C32: =QUARTILE(Raw_Data!$G$2:$G$6001,1) -> 3 | D32: =IF(ABS(B32-C32)<0.001,"OK","CHECK") -> OK
A33: Q3 incident_report_delay_days | B33: 5 | C33: =QUARTILE(Raw_Data!$G$2:$G$6001,3) -> 5 | D33: =IF(ABS(B33-C33)<0.001,"OK","CHECK") -> OK
A34: IQR incident_report_delay_days | B34: 2 | C34: =C33-C32 -> 2 | D34: =IF(ABS(B34-C34)<0.001,"OK","CHECK") -> OK
A36: C. Summary Statistics (days_since_policy_start)
A37: Metric | B37: Notebook output | C37: Excel formula result | D37: Match?
A38: Mean days_since_policy_start | B38: 1838.6305 | C38: =AVERAGE(Raw_Data!$E$2:$E$6001) -> 1838.6305 | D38: =IF(ABS(B38-C38)<0.001,"OK","CHECK") -> OK
A39: Median days_since_policy_start | B39: 1831 | C39: =MEDIAN(Raw_Data!$E$2:$E$6001) -> 1831 | D39: =IF(ABS(B39-C39)<0.001,"OK","CHECK") -> OK
A40: Standard deviation days_since_policy_start | B40: 1048.9359 | C40: =STDEV(Raw_Data!$E$2:$E$6001) -> 1048.9359 | D40: =IF(ABS(B40-C40)<0.001,"OK","CHECK") -> OK
A41: Q1 days_since_policy_start | B41: 949 | C41: =QUARTILE(Raw_Data!$E$2:$E$6001,1) -> 949 | D41: =IF(ABS(B41-C41)<0.001,"OK","CHECK") -> OK
A42: Q3 days_since_policy_start | B42: 2752.5 | C42: =QUARTILE(Raw_Data!$E$2:$E$6001,3) -> 2752.5 | D42: =IF(ABS(B42-C42)<0.001,"OK","CHECK") -> OK
A43: IQR days_since_policy_start | B43: 1803.5 | C43: =C42-C41 -> 1803.5 | D43: =IF(ABS(B43-C43)<0.001,"OK","CHECK") -> OK
A45: D. Claim Amount by Fraud Outcome
A46: Metric | B46: Notebook output | C46: Excel formula result | D46: Match?
A47: Mean claim_amount - legitimate (0) | B47: 2642.8139 | C47: =AVERAGEIF(Raw_Data!$J$2:$J$6001,0,Raw_Data!$D$2:$D$6001) -> 2642.8139 | D47: =IF(ABS(B47-C47)<0.001,"OK","CHECK") -> OK
A48: Mean claim_amount - fraudulent (1) | B48: 2732.884 | C48: =AVERAGEIF(Raw_Data!$J$2:$J$6001,1,Raw_Data!$D$2:$D$6001) -> 2732.884 | D48: =IF(ABS(B48-C48)<0.001,"OK","CHECK") -> OK
...
